Workbook
Name Paving5: 'Project Info Input'!#REF!

Sheet Project Info Input
A2: ESTIMATE INFORMATION
A3: INPUT SHEET
B5: *Fill in Highlighted Cells*
B7: PROJECT INFORMATION | E7: NOTES
B8: Name | C8: Test
B9: Type
B10: Location | C10: Test 1
B11: Client
B12: Estimator
B13: Checked By
B14: New or Renovation
B15: Estimate Date
B16: Last Update
B17: Plans Dated
B18: Specs Dated
B19: Projected Start Date
B21: SCHEDULE INFORMATION
B22: Site Duration | D22: MO
B23: Bldg Duration | D23: MO
B24: Close-out Duration | C24: 0.5 | D24: MO
B25: Project Duration | C25: =SUM(C22:C23) -> 0 | D25: MO
B27: SITE INFORMATION
B28: Site Size (Acres) | D28: AC
B30: BUILDING INFORMATION
B31: Clear Height | C31: 0 | D31: FT
B32: Building Length | C32: 0 | D32: LF
B33: Building Depth | C33: 0 | D33: LF
B34: Roof Area | C34: =C32*C33 -> 0 | D34: SF | E34: adjust SF as necessary to accurately capture total roof SF
B35: Bldg Perimeter | C35: =(C32+C33)*2 -> 0 | D35: LF | E35: adjust LF as necessary to accurately capture total bldg perimeter LF
B36: Floor Areas | I36: Bays & Columns the Depth of Bldg | L36: Bays & Columns the Length of Bldg
B37: Warehouse | C37: =C34-C38-C39-C40-C41-C42 -> 0 | D37: SF
B38: Office | C38: 0 | D38: SF | I38: Depth | J38: =C33 -> 0 | L38: Depth | M38: =C32 -> 0
B39: Office Mezzanine | C39: 0 | D39: SF | I39: Speed Bay(s) | J39: =C52*IF(C48="Cross Dock",2,1) -> 120
B40: Manufacturing | C40: 0 | D40: SF | I40: Interior Bays | J40: =J38-J39 -> -120 | L40: Interior Bays | M40: =M38/C50 -> 0
B41: Maintenance | C41: 0 | D41: SF | I41: Speed Bays | J41: =IF(C48="Cross Dock",2,1) -> 2
B42: Other | C42: 0 | D42: SF | I42: Interior Bays | J42: =J40/C51 -> -2.4
B43: TOTAL: | C43: =IF(SUM(C37:C42)=0,C34,SUM(C37:C42)) -> 0 | D43: SF | I43: TOTAL BAYS | J43: =ROUNDUP(J41+J42,0) -> -1 | L43: TOTAL BAYS | M43: =ROUNDUP(M40,0) -> 0
B44: Total Wall Area - Exterior | I44: Columns | J44: =J43-1 -> -2 | L44: Columns | M44: =M43-1 -> -1
B45: Total Wall Area - Interior
B46: Average Panel Width | C46: 26 | I46: TOTALS
...

Sheet Budget Summary
D2: Client: | E2: =+'Project Info Input'!C11 -> 0 | G2: =+E90 -> 6568.0722 | I2: Grand Total
D3: Project Name: | E3: ='Project Info Input'!C8 -> Test | G3: =F90 -> 0 | I3: /BSF
D4: Location: | E4: ='Project Info Input'!C10 -> Test 1 | G4: ='Project Info Input'!C31 -> 0 | I4: Clear Height
D5: Date: | E5: =IF('Project Info Input'!C16="",'Project Info Input'!C15,'Project Info Input'!C16) -> 0 | G5: =IF('Project Info Input'!C25=0,0,Estimate!I5) -> 0 | I5: Bldg Footprint to Site Ratio
D6: Building Size (SF): | E6: ='Project Info Input'!C43 -> 0 | G6: =IF('Project Info Input'!C25=0,0,Estimate!I6) -> 0 | I6: Wall to Floor Ratio
D7: Size (Acres): | E7: ='Project Info Input'!C28 -> 0 | G7: =IF('Project Info Input'!C25=0,0,Estimate!I7) -> 0 | I7: Pvg to Floor Ratio
B9: Category | C9: CSI Code | D9: Scope of Work | E9: Cost | F9: Cost/SF | G9: Comments
B11: Site Work | C11: 02 40 00 | D11: Demolition | E11: =Estimate!N23 -> 0 | F11: =IF($E$6=0,0,E11/$E$6) -> 0
C12: 31 00 00 | D12: Earthwork | E12: =Estimate!N55 -> 0 | F12: =IF($E$6=0,0,E12/$E$6) -> 0
C13: 31 25 00 | D13: Erosion Control | E13: =Estimate!N39 -> 0 | F13: =IF($E$6=0,0,E13/$E$6) -> 0
C14: 33 10 00 | D14: Site Utilities | E14: =Estimate!N142+Estimate!N166+Estimate!N178+Estimate!N266 -> 0 | F14: =IF($E$6=0,0,E14/$E$6) -> 0
C15: 33 40 00 | D15: Storm Sewer | E15: =Estimate!N96 -> 0 | F15: =IF($E$6=0,0,E15/$E$6) -> 0
C16: 32 00 00 | D16: Concrete Paving | E16: =Estimate!N200 -> 0 | F16: =IF($E$6=0,0,E16/$E$6) -> 0
C17: 32 12 00 | D17: Asphalt Paving | E17: =Estimate!N234 -> 0 | F17: =IF($E$6=0,0,E17/$E$6) -> 0
C18: 32 17 00 | D18: Pavement Markings | E18: =Estimate!N249 -> 0 | F18: =IF($E$6=0,0,E18/$E$6) -> 0
C19: 32 90 00 | D19: Landscaping | E19: =Estimate!N273 -> 0 | F19: =IF($E$6=0,0,E19/$E$6) -> 0
C20: 32 31 00 | D20: Fencing | E20: =Estimate!N285 -> 0 | F20: =IF($E$6=0,0,E20/$E$6) -> 0
C21: 32 32 00 | D21: Retaining Walls | E21: =Estimate!N301 -> 0 | F21: =IF($E$6=0,0,E21/$E$6) -> 0
C22: 32 30 00 | D22: Misc. Site Improvements | E22: =Estimate!N311 -> 0 | F22: =IF($E$6=0,0,E22/$E$6) -> 0
D23: Subtotal - Site Work | E23: =SUM(E11:E22) -> 0 | F23: =IF($E$6=0,0,E23/$E$6) -> 0 | G23: /BSF | L23: =IF(E23=Estimate!N22,"SITEWORK CHECKS","ERROR - CHECK SUMS") -> SITEWORK CHECKS | M23: =E23 -> 0 | N23: =Estimate!N22 -> 0 | O23: =M23-N23 -> 0
F24: =IF($E$7=0,0,E23/$E$7) -> 0 | G24: /ACRE
B26: Building | C26: 03 30 00 | D26: Foundations | E26: =Estimate!N330 -> 0 | F26: =IF($E$6=0,0,E26/$E$6) -> 0
C27: 03 30 00 | D27: Concrete Slab | E27: =Estimate!N362 -> 0 | F27: =IF($E$6=0,0,E27/$E$6) -> 0
C28: 09 33 00 | D28: Concrete Floor Sealer | E28: =Estimate!N382 -> 0 | F28: =IF($E$6=0,0,E28/$E$6) -> 0
C29: 03 47 00 | D29: Concrete Tilt Walls | E29: =Estimate!N390 -> 0 | F29: =IF($E$6=0,0,E29/$E$6) -> 0
C30: 03 48 00 | D30: Misc. Concrete | E30: =Estimate!N404 -> 0 | F30: =IF($E$6=0,0,E30/$E$6) -> 0
C31: 04 00 00 | D31: Masonry | E31: =Estimate!N417 -> 0 | F31: =IF($E$6=0,0,E31/$E$6) -> 0
C32: 05 00 00 | D32: Structural Steel & Erection | E32: =Estimate!N429+Estimate!N478+Estimate!N495 -> 0 | F32: =IF($E$6=0,0,E32/$E$6) -> 0
C33: 05 50 00 | D33: Misc. Metals | E33: =Estimate!N455 -> 4500 | F33: =IF($E$6=0,0,E33/$E$6) -> 0
C34: 06 10 00 | D34: Rough Carpentry | E34: =Estimate!N511 -> 0 | F34: =IF($E$6=0,0,E34/$E$6) -> 0
C35: 06 20 00 | D35: Finish Carpentry | E35: =Estimate!N519 -> 0 | F35: =IF($E$6=0,0,E35/$E$6) -> 0
C36: 07 00 00 | D36: Insulation | E36: =Estimate!N540 -> 0 | F36: =IF($E$6=0,0,E36/$E$6) -> 0
C37: 07 40 00 | D37: Canopies | E37: =Estimate!N559 -> 0 | F37: =IF($E$6=0,0,E37/$E$6) -> 0
C38: 07 42 00 | D38: Insulated Metal Wall Panels | E38: =Estimate!N570 -> 0 | F38: =IF($E$6=0,0,E38/$E$6) -> 0
C39: 07 50 00 | D39: Roofing | E39: =Estimate!N582 -> 0 | F39: =IF($E$6=0,0,E39/$E$6) -> 0
C40: 07 92 00 | D40: Sealants & Caulking | E40: =Estimate!N607 -> 0 | F40: =IF($E$6=0,0,E40/$E$6) -> 0
C41: 08 00 00 | D41: Doors, Frames & Hardware | E41: =Estimate!N624+Estimate!N635 -> 550 | F41: =IF($E$6=0,0,E41/$E$6) -> 0
C42: 08 30 00 | D42: Overhead Doors | E42: =Estimate!N647 -> 0 | F42: =IF($E$6=0,0,E42/$E$6) -> 0
C43: 08 40 00 | D43: Storefront, Glass & Glazing | E43: =Estimate!N665 -> 0 | F43: =IF($E$6=0,0,E43/$E$6) -> 0
C44: 09 20 00 | D44: Framing & Drywall | E44: =Estimate!N687 -> 0 | F44: =IF($E$6=0,0,E44/$E$6) -> 0
...

Sheet Estimate
E1: estimate checks | F1: =IF(SUM(U9:U1270)=0,"GOOD TO GO","") -> GOOD TO GO | G1: =IF(SUM(U9:U1270)=0,"","UH OH, YOU MESSED UP")
F2: Client: | G2: =+'Project Info Input'!C11 -> 0 | I2: =+N1269 -> 6568.0722 | J2: Grand Total | Q2: Site | R2: ='Budget Summary'!E23 -> 0 | S2: =IFERROR(R2/$G$6,0) -> 0
F3: Project Name: | G3: ='Project Info Input'!C8 -> Test | I3: =O1269 -> 0 | J3: /BSF | Q3: Building | R3: ='Budget Summary'!E63 -> 6183.99 | S3: =IFERROR(R3/$G$6,0) -> 0
F4: Location: | G4: ='Project Info Input'!C10 -> Test 1 | I4: ='Project Info Input'!C31 -> 0 | J4: Clear Height | Q4: GC's and Fees | R4: ='Budget Summary'!E74 -> 384.08221 | S4: =IFERROR(R4/$G$6,0) -> 0
F5: Date: | G5: ='Budget Summary'!E5 -> 0 | I5: =G6/(G7*43560) -> #DIV/0! | J5: Bldg Footprint to Site Ratio | Q5: Allowances | R5: ='Budget Summary'!E88 -> 0 | S5: =IFERROR(R5/$G$6,0) -> 0
F6: Building Size (SF): | G6: ='Project Info Input'!C43 -> 0 | I6: =G392/G6 -> #DIV/0! | J6: Wall to Floor Ratio
F7: Size (Acres): | G7: ='Project Info Input'!C28 -> 0 | I7: =(SUM(G202:G206)+(SUM(G236:G239)*9))/G6 -> #DIV/0! | J7: Pvg to Floor Ratio | Q7: ESTIMATE CHECK FORMULAS ENTERED BELOW IN THESE COLUMNS
A8: Filter | B8: Bid Form Mapping | C8: Subcontractor Name | D8: CSI | E8: Work Description | F8: Details | G8: Quantity | H8: Unit | I8: $/Unit | J8: Cntrl Est Line Item Total | K8: INC | L8: SUB QUOTE | M8: BUDGET | N8: Grand Total | O8: $/SF
A9: x | E9: GENERAL CONDITIONS | G9: =SUM(G10:G12) -> 0 | H9: MOS | I9: =N9/G9 -> #DIV/0! | N9: =SUM(N10:N21) -> 0 | O9: =IFERROR(N9/$G$6,0) -> 0 | Q9: =IF(SUM(M10:M21)=SUM(N10:N21),"SUBTOTALS MATCH LINE ITEM TOTALS","ERROR- CHECK SUMS") -> SUBTOTALS MATCH LINE ITEM TOTALS | S9: =SUM(M10:M21) -> 0 | T9: =SUM(N10:N21) -> 0 | U9: =S9-T9 -> 0
A10: x | D10: 01 | E10: GENERAL CONDITIONS | N10: =SUM(M10:M13) -> 0 | O10: =IFERROR(N10/$G$6,0) -> 0 | Q10: =IF(SUM(M10:M21)=N9,"DIVISION TOTAL MATCHES LINE ITEM TOTALS","ERROR- CHECK SUMS") -> DIVISION TOTAL MATCHES LINE ITEM TOTALS | S10: =SUM(M10:M21) -> 0 | T10: =N9 -> 0 | U10: =S10-T10 -> 0
A11: x | D11: 01 00 00 | E11: Site GCs | G11: ='Project Info Input'!C22 -> 0 | H11: MO | I11: ='General Conditions'!H129 -> 0 | J11: =G11*I11 -> 0 | M11: =IF(K11="x","Included in Sub Bid",J11) -> 0 | Q11: =IF(N9=SUM(N10:N21),"DIVISION TOTAL MATCHES SUBTOTALS","ERROR- SUBTOTALS") -> DIVISION TOTAL MATCHES SUBTOTALS | S11: =N9 -> 0 | T11: =SUM(N10:N21) -> 0 | U11: =S11-T11 -> 0
A12: x | D12: 01 00 00 | E12: Building GCs | G12: ='Project Info Input'!C23 -> 0 | H12: MO | I12: ='General Conditions'!H129 -> 0 | J12: =G12*I12 -> 0 | M12: =IF(K12="x","Included in Sub Bid",J12) -> 0
A13: x | D13: 01 00 00 | E13: Closeout GCs | G13: ='Project Info Input'!C24 -> 0.5 | H13: MO | I13: =I11/2 -> 0 | J13: =G13*I13 -> 0 | M13: =IF(K13="x","Included in Sub Bid",J13) -> 0
A14: x | D14: 01 | E14: MOBILIZATION | N14: =SUM(M15:M16) -> 0 | O14: =IFERROR(N14/$G$6,0) -> 0
A15: x | D15: 01 00 00 | E15: Mobilization | G15: 1 | H15: LS | J15: =G15*I15 -> 0 | M15: =IF(K15="x","Included in Sub Bid",J15) -> 0
A16: x | D16: 01 00 00 | E16: Web Cam | H16: MO | I16: 600 | J16: =G16*I16 -> 0 | M16: =IF(K16="x","Included in Sub Bid",J16) -> 0
A17: x | D17: 01 | E17: FINAL CLEANING | N17: =SUM(M18:M21) -> 0 | O17: =IFERROR(N17/$G$6,0) -> 0
A18: x | D18: 01 00 00 | E18: Warehouse | G18: ='Project Info Input'!C34-Estimate!G19 -> 0 | H18: SF | I18: 0.05 | J18: =G18*I18 -> 0 | M18: =IF(K18="x","Included in Sub Bid",J18) -> 0
A19: x | D19: 01 00 00 | E19: Office | G19: ='Project Info Input'!C38 -> 0 | H19: SF | I19: 0.35 | J19: =G19*I19 -> 0 | M19: =IF(K19="x","Included in Sub Bid",J19) -> 0
A20: x
A21: x
A22: =IF(J22=0,"Exclude","x") -> Exclude | E22: SITEWORK | J22: =SUBTOTAL(9,J23:J327) -> 0 | K22: =IFERROR(J22/$G$6,0) -> 0 | N22: =SUM(N23:N327) -> 0 | O22: =IFERROR(N22/$G$6,0) -> 0 | Q22: =IF(SUM(M23:M327)=SUM(N23:N327),"SUBTOTALS MATCH LINE ITEM TOTALS","ERROR- CHECK SUMS") -> SUBTOTALS MATCH LINE ITEM TOTALS | S22: =SUM(M23:M327) -> 0 | T22: =SUM(N23:N327) -> 0 | U22: =S22-T22 -> 0
A23: =IF(J23=0,"Exclude","x") -> Exclude | D23: 02 | E23: DEMOLITION | J23: =SUBTOTAL(9,J24:J38) -> 0 | K23: =IFERROR(J23/$G$6,0) -> 0 | N23: =SUM(M24:M38) -> 0 | O23: =IFERROR(N23/$G$6,0) -> 0 | Q23: =IF(SUM(M23:M327)=N22,"DIVISION TOTAL MATCHES LINE ITEM TOTALS","ERROR- CHECK SUMS") -> DIVISION TOTAL MATCHES LINE ITEM TOTALS | S23: =SUM(M23:M327) -> 0 | T23: =N22 -> 0 | U23: =S23-T23 -> 0
A24: =A23 -> Exclude | D24: 02 40 00 | E24: Sub Bid | L24: 0 | M24: =L24 -> 0
A25: =A24 -> Exclude | D25: 02 40 00 | E25: Walls | H25: LF | J25: =G25*I25 -> 0 | M25: =IF(K25="x","Included in Sub Bid",J25) -> 0 | Q25: =IF(N22=SUM(N23:N327),"DIVISION TOTAL MATCHES SUBTOTALS","ERROR- SUBTOTALS") -> DIVISION TOTAL MATCHES SUBTOTALS | S25: =N22 -> 0 | T25: =SUM(N23:N327) -> 0 | U25: =S25-T25 -> 0
A26: =A25 -> Exclude | D26: 02 40 00 | E26: Doors | H26: EA | I26: 3500 | J26: =G26*I26 -> 0 | M26: =IF(K26="x","Included in Sub Bid",J26) -> 0
A27: =A26 -> Exclude | D27: 02 40 00 | E27: Flooring | H27: SF | I27: 48 | J27: =G27*I27 -> 0 | M27: =IF(K27="x","Included in Sub Bid",J27) -> 0
A28: =A27 -> Exclude | D28: 02 40 00 | E28: Ceilings | H28: SF | I28: 400 | J28: =G28*I28 -> 0 | M28: =IF(K28="x","Included in Sub Bid",J28) -> 0
A29: =A28 -> Exclude | D29: 02 40 00 | E29: Masonry | H29: SF | I29: 550 | J29: =G29*I29 -> 0 | M29: =IF(K29="x","Included in Sub Bid",J29) -> 0
A30: =A29 -> Exclude | D30: 02 40 00 | E30: Cut openings in existing panels | H30: EA | J30: =G30*I30 -> 0 | M30: =IF(K30="x","Included in Sub Bid",J30) -> 0
A31: =A30 -> Exclude | D31: 02 40 00 | E31: Asphalt | H31: SF | J31: =G31*I31 -> 0 | M31: =IF(K31="x","Included in Sub Bid",J31) -> 0
A32: =A31 -> Exclude | D32: 02 40 00 | E32: Curb Cut | H32: EA | I32: 3500 | J32: =G32*I32 -> 0 | M32: =IF(K32="x","Included in Sub Bid",J32) -> 0
A33: =A32 -> Exclude | D33: 02 40 00 | E33: Curb | H33: SF | J33: =G33*I33 -> 0 | M33: =IF(K33="x","Included in Sub Bid",J33) -> 0
A34: =A33 -> Exclude | D34: 02 40 00 | E34: Concrete Paving | H34: SF | J34: =G34*I34 -> 0 | M34: =IF(K34="x","Included in Sub Bid",J34) -> 0
A35: =A34 -> Exclude | D35: 02 40 00 | E35: Subcontractor Adjustment | H35: LS | M35: =IF(K35="x","Included in Sub Bid",G35*I35) -> 0
A36: =A35 -> Exclude | D36: 02 40 00 | E36: Bid Day Cut | H36: LS | M36: =IF(K36="x","Included in Sub Bid",G36*I36) -> 0
A37: =A36 -> Exclude
A38: =A37 -> Exclude
A39: =IF(J39=0,"Exclude","x") -> Exclude | D39: 31 | E39: EROSION CONTROL | J39: =SUBTOTAL(9,J40:J54) -> 0 | K39: =IFERROR(J39/$G$6,0) -> 0 | N39: =SUM(M40:M54) -> 0 | O39: =IFERROR(N39/$G$6,0) -> 0
A40: =A39 -> Exclude | D40: 31 25 00 | E40: Sub Bid | L40: 0 | M40: =L40 -> 0
...

Sheet Clarifications
E3: Clarifications
E4: ='Project Info Input'!C8 -> Test
E5: ='Project Info Input'!C10 -> Test 1
E6: ='Project Info Input'!C15 -> 0
A8: GENERAL
A9: 1 | B9: Estimate is based on the following:
B10: a. | C10: Plans prepared by XX dated XX
B11: b. | C11: Specifications prepared by XX dated XX
B12: c. | C12: Geotechnical Report prepared by XX dated XX
A13: 2 | B13: Pricing is based on a | E13: ='Project Info Input'!C25 -> 0 | F13: month construction schedule.
A14: 3 | B14: Pricing is good for thirty (30) days.
A15: 4 | B15: Design is included/excluded (move to exclusions if excluded).
B16: Civil -
B17: Structural -
B18: Architectural -
B19: MEP/F - Design Build
A20: 5 | B20: Builders Risk Insurance is included/excluded/

Sheet GCs Input, Staff & IT Costs
B2: GCs INPUT | I2: STAFFING RATES
I3: Position | J3: Avg Sal | K3: Monthly Rate | L3: Hourly Rate | M3: New Rate | N3: Old Rate | O3: Old Salary
B4: Project Name | C4: ='Project Info Input'!C8 -> Test | I4: Project Executive | J4: 170000 | K4: =+J4/12 -> 14166.667 | L4: =+J4/2080 -> 81.730769 | M4: =+L4*1.4 -> 114.42308 | P4: Yes
B5: Start Date | C5: ='Project Info Input'!C19 -> 0 | I5: Senior Project Manager | J5: 142000 | K5: =+J5/12 -> 11833.333 | L5: =+J5/2080 -> 68.269231 | M5: =+L5*1.4 -> 95.576923 | N5: 125 | O5: =N5*2080/1.4 -> 185714.29 | P5: No
B6: Project Length (mos) | C6: ='Project Info Input'!C25 -> 0 | I6: Project Manager | J6: 120000 | K6: =+J6/12 -> 10000 | L6: =+J6/2080 -> 57.692308 | M6: =+L6*1.4 -> 80.769231 | N6: 105 | O6: =N6*2080/1.4 -> 156000
I7: Assistant Project Manager | J7: 85000 | K7: =+J7/12 -> 7083.3333 | L7: =+J7/2080 -> 40.865385 | M7: =+L7*1.4 -> 57.211538 | N7: 65 | O7: =N7*2080/1.4 -> 96571.429
B8: Personnel | C8: Needed | D8: Months | E8: % | F8: Monthly Rate | I8: Assistant Project Manager | J8: 85000 | K8: =+J8/12 -> 7083.3333 | L8: =+J8/2080 -> 40.865385 | M8: =+L8*1.4 -> 57.211538 | N8: 65 | O8: =N8*2080/1.4 -> 96571.429
I9: Project Engineer | J9: 55000 | K9: =+J9/12 -> 4583.3333 | L9: =+J9/2080 -> 26.442308 | M9: =+L9*1.4 -> 37.019231 | O9: =N9*2080/1.4 -> 0
B10: Preconstruction | C10: FALSE | D10: Flat fee | E10: Flat fee | F10: 1000 | I10: Project Coordinator | J10: 81000 | K10: =+J10/12 -> 6750 | L10: =+J10/2080 -> 38.942308 | M10: =+L10*1.4 -> 54.519231 | N10: 55 | O10: =N10*2080/1.4 -> 81714.286
B11: General Super | C11: FALSE | D11: =+$C$6 -> 0 | E11: Flat fee | F11: =750/2 -> 375 | I11: Senior Superintendent | J11: 135000 | K11: =+J11/12 -> 11250 | L11: =+J11/2080 -> 64.903846 | M11: =+L11*1.4 -> 90.865385 | N11: 95 | O11: =N11*2080/1.4 -> 141142.86
B12: Safety Manager | C12: FALSE | D12: =+$C$6 -> 0 | E12: Flat fee | F12: 750 | I12: Superintendent | J12: 120000 | K12: =+J12/12 -> 10000 | L12: =+J12/2080 -> 57.692308 | M12: =+L12*1.4 -> 80.769231 | N12: 95 | O12: =N12*2080/1.4 -> 141142.86
B13: Compliance | C13: FALSE | D13: =+$C$6 -> 0 | E13: Flat fee | F13: =750/2 -> 375 | I13: Assistant Superintedent | J13: 85000 | K13: =+J13/12 -> 7083.3333 | L13: =+J13/2080 -> 40.865385 | M13: =+L13*1.4 -> 57.211538 | N13: 65 | O13: =N13*2080/1.4 -> 96571.429
B14: Project Executive | C14: FALSE | D14: =+$C$6 -> 0 | E14: 0.5 | F14: =+'GCs Input, Staff & IT Costs'!K4 -> 14166.667 | I14: Assistant Superintedent | J14: 85000 | K14: =+J14/12 -> 7083.3333 | L14: =+J14/2080 -> 40.865385 | M14: =+L14*1.4 -> 57.211538 | N14: 65 | O14: =N14*2080/1.4 -> 96571.429
I15: Safety Manager | J15: 130000 | K15: =(J15/12)/35 -> 309.52381 | L15: =+J15/2080 -> 62.5 | M15: =+L15*1.4 -> 87.5 | N15: 125 | O15: =N15*2080/1.4 -> 185714.29
B16: On-Site Safety | C16: FALSE | D16: =+$C$6 -> 0 | E16: 1 | F16: =+'GCs Input, Staff & IT Costs'!K18 -> 7916.6667 | I16: Compliance | J16: 200000 | K16: =(J16/12)/35 -> 476.19048 | L16: =+J16/2080 -> 96.153846 | M16: =+L16*1.4 -> 134.61538 | N16: 145 | O16: =N16*2080/1.4 -> 215428.57
I17: Accounting | J17: 74000 | K17: =+J17/12 -> 6166.6667 | L17: =+J17/2080 -> 35.576923 | M17: =+L17*1.4 -> 49.807692 | N17: 50 | O17: =N17*2080/1.4 -> 74285.714
B18: Senior Project Manager | C18: FALSE | D18: =+$C$6 -> 0 | E18: 0.5 | F18: =+'GCs Input, Staff & IT Costs'!K5 -> 11833.333 | I18: On-Site Safety | J18: 95000 | K18: =+J18/12 -> 7916.6667 | L18: =+J18/2080 -> 45.673077 | M18: =+L18*1.4 -> 63.942308 | N18: 75 | O18: =N18*2080/1.4 -> 111428.57
B19: Project Manager | C19: FALSE | D19: =+$C$6 -> 0 | E19: 0.33 | F19: =+'GCs Input, Staff & IT Costs'!K6 -> 10000 | I19: General Superintendent | J19: 175000 | K19: =(J19/12)/35 -> 416.66667 | L19: =+J19/2080 -> 84.134615 | M19: =+L19*1.4 -> 117.78846 | N19: 135 | O19: =N19*2080/1.4 -> 200571.43
B20: Assistant Project Manager | C20: FALSE | D20: =+$C$6 -> 0 | E20: 0.33 | F20: =+'GCs Input, Staff & IT Costs'!K7 -> 7083.3333
B21: Assistant Project Manager | C21: FALSE | D21: =+$C$6 -> 0 | E21: 0.33 | F21: =+'GCs Input, Staff & IT Costs'!K8 -> 7083.3333
I22: IT COSTS
B23: Senior Superintendent | C23: FALSE | D23: =+$C$6 -> 0 | E23: 1 | F23: =+'GCs Input, Staff & IT Costs'!K11 -> 11250 | I23: IT Support Cost | J23: 55.56 | K23: IT Salary X 2 to account for all expenses with half for corporate use and half for user support. Divided by number of users, divided by 12
B24: Superintendent | C24: FALSE | D24: =+$C$6 -> 0 | E24: 1 | F24: =+'GCs Input, Staff & IT Costs'!K12 -> 10000 | I24: Desktop Management software | J24: 4.58 | K24: $55 per year, divided by 12 months
B25: Assistant Superintendent | C25: FALSE | D25: =+$C$6 -> 0 | E25: 0.33 | F25: =+'GCs Input, Staff & IT Costs'!K13 -> 7083.3333 | I25: Antivirus | J25: 5.23 | K25: TrendMicro Worry Free Service for Business + DeepArmor
B26: Assistant Superintendent | C26: FALSE | D26: =+$C$6 -> 0 | E26: 1 | F26: =+'GCs Input, Staff & IT Costs'!K14 -> 7083.3333 | I26: Laptop | J26: 41.67 | K26: $1500 divided by 36 months
I27: Microsoft Office 365 | J27: 27 | K27: Includes a portion of Project used by PMs, APMs, and PCs
B28: Field Clerk | C28: FALSE | D28: =+$C$6 -> 0 | E28: 0.4 | F28: 1000 | I28: Mifi | J28: 58.58
B29: Project Coordinator | C29: FALSE | D29: =+$C$6 -> 0 | E29: 0.3 | F29: =+'GCs Input, Staff & IT Costs'!K10 -> 6750 | I29: Vista Viewpoint | J29: 38.88
B30: Accounting | C30: FALSE | D30: =+$C$6 -> 0 | E30: 0.3 | F30: =+'GCs Input, Staff & IT Costs'!K17 -> 6166.6667 | I30: Firewall | J30: 8.68 | K30: 1\2 of our $25,000py Frirewall spending (1/2 corp burden) divided by 12 months, spread over 100 users
B31: Scheduling Consultant | C31: FALSE | D31: =+$C$6 -> 0 | E31: 0.4 | F31: 3500 | I31: Security Cost | J31: 4.17 | K31: Penitration and hacking vulnerability testing per month spread over 100 users
B32: Temporary Labor | C32: FALSE | D32: =+$C$6 -> 0 | E32: 0.35 | F32: 1000 | I32: Total | J32: =SUM(J23:J31) -> 244.35
J33: 250 | K33: includes server upgrade and new cloud services
B34: Costs | C34: Flat Cost
B36: Vehicle | C36: 875
B37: Fuel | C37: 400
B38: Phone | C38: 150
B39: Travel & Per Diem | C39: 860
B40: Temporary Housing? | C40: TRUE | S40: Yes
B41: On-Site Safety | C41: =IF($C$40=TRUE,1500,0) -> 1500 | S41: No
B42: Senior PM | C42: =IF($C$40=TRUE,2500,0) -> 2500
...

Sheet General Conditions
F2: ='GCs Input, Staff & IT Costs'!C4 -> Test | N2: SUMMARY
N3: =H129 -> 0 | O3: /Month
N4: ='Project Info Input'!C22+'Project Info Input'!C23 -> 0 | O4: Months
F5: General Conditions
P6: To hide rows,
P7: click on filter &
B8: Personnel | F8: % of Month | G8: # of Months | H8: Rate | I8: Burden Rate | J8: Monthly Rate | K8: Adjustments | L8: Total | P8: uncheck "remove"
P9: keep
B10: Preconstruction | F10: =IF('GCs Input, Staff & IT Costs'!C10=TRUE,'GCs Input, Staff & IT Costs'!E10,"None") -> None | G10: Flat fee | H10: =IF(F10="None",0,'GCs Input, Staff & IT Costs'!F10) -> 0 | I10: =+H10*10 -> 0 | J10: =IF('Project Info Input'!C25=0,0,+I10) -> 0 | L10: =+J10+K10 -> 0 | P10: =IF(L10=0,"remove","keep") -> remove
P11: keep
B12: Project Executive | F12: =IF('GCs Input, Staff & IT Costs'!C14=TRUE,'GCs Input, Staff & IT Costs'!E14,"None") -> None | G12: Flat fee | H12: =IF(F12="None",0,'GCs Input, Staff & IT Costs'!F14) -> 0 | I12: =IFERROR(+H12*1.4,0) -> 0 | J12: =IF('Project Info Input'!C25=0,0,IFERROR(I12*F12,0)) -> 0 | L12: =+J12+K12 -> 0 | P12: =IF(L12=0,"remove","keep") -> remove
P13: keep
B14: General Super | F14: =IF('GCs Input, Staff & IT Costs'!C11=TRUE,'GCs Input, Staff & IT Costs'!E11,"None") -> None | G14: ='GCs Input, Staff & IT Costs'!D11 -> 0 | H14: =IF(F14="None",0,'GCs Input, Staff & IT Costs'!F11) -> 0 | I14: =IFERROR(+H14*1.4,0) -> 0 | J14: =IF('Project Info Input'!C25=0,0,+I14) -> 0 | L14: =IFERROR(J14*G14,0)+(K14*G14) -> 0 | P14: =IF(L14=0,"remove","keep") -> remove
P15: keep
B16: Safety Manager | F16: =IF('GCs Input, Staff & IT Costs'!C12=TRUE,'GCs Input, Staff & IT Costs'!E12,"None") -> None | G16: ='GCs Input, Staff & IT Costs'!D12 -> 0 | H16: =IF(F16="None",0,'GCs Input, Staff & IT Costs'!F12) -> 0 | I16: =IFERROR(+H16*1.4,0) -> 0 | J16: =IF('Project Info Input'!C25=0,0,+I16) -> 0 | L16: =IFERROR(J16*G16,0)+(K16*G16) -> 0 | P16: =IF(L16=0,"remove","keep") -> remove
P17: keep
B18: Compliance | F18: =IF('GCs Input, Staff & IT Costs'!C13=TRUE,'GCs Input, Staff & IT Costs'!E13,"None") -> None | G18: ='GCs Input, Staff & IT Costs'!D13 -> 0 | H18: =IF(F18="None",0,'GCs Input, Staff & IT Costs'!F13) -> 0 | I18: =IFERROR(+H18*1.4,0) -> 0 | J18: =IF('Project Info Input'!C25=0,0,+I18) -> 0 | L18: =IFERROR(J18*G18,0)+(K18*G18) -> 0 | P18: =IF(L18=0,"remove","keep") -> remove
P19: keep
B20: On-Site Safety | F20: =IF('GCs Input, Staff & IT Costs'!C16=TRUE,'GCs Input, Staff & IT Costs'!E16,"None") -> None | G20: =G21 -> 0 | H20: =SUM(H21:H26) -> 0 | J20: =IF('Project Info Input'!C25=0,0,SUM(J21:J26)) -> 0 | K20: =SUM(K21:K26) -> 0 | L20: =SUM(L21:L26) -> 0 | P20: =IF(L21=0,"remove","keep") -> remove
B21: Salary | G21: ='GCs Input, Staff & IT Costs'!D16 -> 0 | H21: =IF(F20="None",0,'GCs Input, Staff & IT Costs'!F16) -> 0 | I21: =IFERROR(+H21*1.4,0) -> 0 | J21: =IFERROR(I21*F20,0) -> 0 | L21: =IFERROR(J21*G21,0)+(K21*G21) -> 0
B22: Vehicle | G22: =G21 -> 0 | H22: =IF(F20="None",0,'GCs Input, Staff & IT Costs'!$C$36) -> 0 | J22: =IFERROR(+H22*$F$20,0) -> 0 | L22: =IFERROR(J22*G22,0)+(K22*G22) -> 0 | P22: =IF(L22=0,"remove","keep") -> remove
B23: Fuel | G23: =G22 -> 0 | H23: =IF(F20="None",0,'GCs Input, Staff & IT Costs'!$C$37) -> 0 | J23: =IFERROR(+H23*$F$20,0) -> 0 | L23: =IFERROR(J23*G23,0)+(K23*G23) -> 0 | P23: =IF(L23=0,"remove","keep") -> remove
B24: Phone | G24: =G23 -> 0 | H24: =IF(F20="None",0,'GCs Input, Staff & IT Costs'!$C$38) -> 0 | J24: =IFERROR(+H24*$F$20,0) -> 0 | L24: =IFERROR(J24*G24,0)+(K24*G24) -> 0 | P24: =IF(L24=0,"remove","keep") -> remove
B25: Travel & Per Diem | G25: =G24 -> 0 | H25: =IF(F20="None",0,'GCs Input, Staff & IT Costs'!$C$39) -> 0 | J25: =IFERROR(+H25,0) -> 0 | L25: =IFERROR(J25*G25,0)+(K25*G25) -> 0 | P25: =IF(L25=0,"remove","keep") -> remove
B26: Temporary Housing | G26: =G25 -> 0 | H26: =IF(F20="None",0,'GCs Input, Staff & IT Costs'!$C$41) -> 0 | J26: =IFERROR(+H26*$F$20,0) -> 0 | L26: =IFERROR(J26*G26,0)+(K26*G26) -> 0 | P26: =IF(L26=0,"remove","keep") -> remove
P27: keep
B28: Senior Project Manager | F28: =IF('GCs Input, Staff & IT Costs'!C18=TRUE,'GCs Input, Staff & IT Costs'!E18,"None") -> None | G28: =G29 -> 0 | H28: =SUM(H29:H34) -> 0 | J28: =IF('Project Info Input'!C25=0,0,SUM(J29:J34)) -> 0 | K28: =SUM(K29:K34) -> 0 | L28: =SUM(L29:L34) -> 0 | P28: =IF(L29=0,"remove","keep") -> remove
B29: Salary | G29: ='GCs Input, Staff & IT Costs'!D18 -> 0 | H29: =IF(F28="None",0,'GCs Input, Staff & IT Costs'!F18) -> 0 | I29: =IFERROR(+H29*1.4,0) -> 0 | J29: =IFERROR(I29*F28,0) -> 0 | L29: =IFERROR(J29*G29,0)+(K29*G29) -> 0
B30: Vehicle | G30: =G29 -> 0 | H30: =IF(F28="None",0,'GCs Input, Staff & IT Costs'!$C$36) -> 0 | J30: =IFERROR(+H30*$F$28,0) -> 0 | L30: =IFERROR(J30*G30,0)+(K30*G30) -> 0 | P30: =IF(L30=0,"remove","keep") -> remove
B31: Fuel | G31: =G30 -> 0 | H31: =IF(F28="None",0,'GCs Input, Staff & IT Costs'!$C$37) -> 0 | J31: =IFERROR(+H31*$F$28,0) -> 0 | L31: =IFERROR(J31*G31,0)+(K31*G31) -> 0 | P31: =IF(L31=0,"remove","keep") -> remove
B32: Phone | G32: =G31 -> 0 | H32: =IF(F28="None",0,'GCs Input, Staff & IT Costs'!$C$38) -> 0 | J32: =IFERROR(+H32*$F$28,0) -> 0 | L32: =IFERROR(J32*G32,0)+(K32*G32) -> 0 | P32: =IF(L32=0,"remove","keep") -> remove
B33: Travel & Per Diem | G33: =G32 -> 0 | H33: =IF(F28="None",0,'GCs Input, Staff & IT Costs'!$C$39) -> 0 | J33: =IFERROR(+H33,0) -> 0 | L33: =IFERROR(J33*G33,0)+(K33*G33) -> 0 | P33: =IF(L33=0,"remove","keep") -> remove
B34: Temporary Housing | G34: =G33 -> 0 | H34: =IF(F28="None",0,'GCs Input, Staff & IT Costs'!$C$42) -> 0 | J34: =IFERROR(+H34*$F$28,0) -> 0 | L34: =IFERROR(J34*G34,0)+(K34*G34) -> 0 | P34: =IF(L34=0,"remove","keep") -> remove
P35: keep
B36: Project Manager | F36: =IF('GCs Input, Staff & IT Costs'!C19=TRUE,'GCs Input, Staff & IT Costs'!E19,"None") -> None | G36: =G37 -> 0 | H36: =SUM(H37:H42) -> 0 | J36: =IF('Project Info Input'!C25=0,0,SUM(J37:J42)) -> 0 | K36: =SUM(K37:K42) -> 0 | L36: =SUM(L37:L42) -> 0 | P36: =IF(L37=0,"remove","keep") -> remove
B37: Salary | G37: ='GCs Input, Staff & IT Costs'!D19 -> 0 | H37: =IF(F36="None",0,'GCs Input, Staff & IT Costs'!F19) -> 0 | I37: =IFERROR(+H37*1.4,0) -> 0 | J37: =IFERROR(I37*F36,0) -> 0 | L37: =IFERROR(J37*G37,0)+(K37*G37) -> 0
B38: Vehicle | G38: =G37 -> 0 | H38: =IF(F36="None",0,'GCs Input, Staff & IT Costs'!$C$36) -> 0 | J38: =IFERROR(+H38*$F$36,0) -> 0 | L38: =IFERROR(J38*G38,0)+(K38*G38) -> 0 | P38: =IF(L38=0,"remove","keep") -> remove
B39: Fuel | G39: =G38 -> 0 | H39: =IF(F36="None",0,'GCs Input, Staff & IT Costs'!$C$37) -> 0 | J39: =IFERROR(+H39*$F$36,0) -> 0 | L39: =IFERROR(J39*G39,0)+(K39*G39) -> 0 | P39: =IF(L39=0,"remove","keep") -> remove
B40: Phone | G40: =G39 -> 0 | H40: =IF(F36="None",0,'GCs Input, Staff & IT Costs'!$C$38) -> 0 | J40: =IFERROR(+H40*$F$36,0) -> 0 | L40: =IFERROR(J40*G40,0)+(K40*G40) -> 0 | P40: =IF(L40=0,"remove","keep") -> remove
B41: Travel & Per Diem | G41: =G40 -> 0 | H41: =IF(F36="None",0,'GCs Input, Staff & IT Costs'!$C$39) -> 0 | J41: =IFERROR(+H41,0) -> 0 | L41: =IFERROR(J41*G41,0)+(K41*G41) -> 0 | P41: =IF(L41=0,"remove","keep") -> remove
...

Sheet Estimate Risk Summary
B2: ESTIMATE RISK SUMMARY
B4: Project | C4: ='Project Info Input'!C8 -> Test
B5: Lead Estimator Name | C5: ='Project Info Input'!C12 -> 0
B6: Reviewing Estimator Name | C6: ='Project Info Input'!C13 -> 0
B8: Scope | C8: # of Bids | D8: % Spread Btwn Low Bids | E8: Adjustments | F8: Bid Day Cuts | G8: Exposure/Risk | H8: Savings | I8: Anticipated Buy Out | J8: Comment | O8: PROJECT NAME | P8: LOCATION | Q8: VOLUME | R8: FEE | S8: FEE ON ALLOWANCES | T8: TOTAL FEE | U8: FEE % | V8: BID DAY BUYOUT | W8: FEE + 1/2 BUYOUT | X8: FEE + BUYOUT | Y8: PROJECTED START
B9: Demolition | E9: =Estimate!M35 -> 0 | F9: =Estimate!M36 -> 0 | G9: DELETE | I9: MANUAL PLUG | J9: ADD SUB CARRIED | O9: ='Budget Summary'!E3 -> Test | P9: ='Budget Summary'!E4 -> Test 1 | Q9: ='Budget Summary'!G2 -> 6568.0722 | R9: =Estimate!N1247 -> 312.76534 | S9: =Estimate!N1253-(Estimate!N1253/(1+U9)) -> 0 | T9: =R9+S9 -> 312.76534 | U9: =Estimate!G1249+Estimate!G1250 -> 0.05 | V9: =I45 -> 0 | W9: =T9+V9*0.5 -> 312.76534 | X9: =T9+V9 -> 312.76534 | Y9: ='Project Info Input'!C19 -> 0
B10: Earthwork | E10: =Estimate!M92+Estimate!M51 -> 0 | F10: =Estimate!M93+Estimate!M52 -> 0 | G10: =F10 -> 0 | I10: =G10+H10 -> 0 | O10: ='Budget Summary'!E4 -> Test 1 | P10: ='Budget Summary'!E5 -> 0 | Q10: ='Budget Summary'!G3 -> 0 | R10: =Estimate!N1248 -> 312.76534 | S10: =Estimate!N1254-(Estimate!N1254/(1+U10)) -> 0 | T10: =R10+S10 -> 312.76534 | U10: =Estimate!G1250+Estimate!G1251 -> 0.03 | V10: =I46 -> 0 | W10: =T10+V10*0.5 -> 312.76534 | X10: =T10+V10 -> 312.76534 | Y10: ='Project Info Input'!C20 -> 0
B11: Storm Sewer | E11: =Estimate!M138 -> 0 | F11: =Estimate!M139 -> 0 | G11: =F11 -> 0 | I11: =G11+H11 -> 0
B12: Fire Water | E12: =Estimate!M162 -> 0 | F12: =Estimate!M163 -> 0 | G12: =F12 -> 0 | I12: =G12+H12 -> 0
B13: Domestic Water | E13: =Estimate!M174 -> 0 | F13: =Estimate!M175 -> 0 | G13: =F13 -> 0 | I13: =G13+H13 -> 0
B14: Sanitary Sewer | E14: =Estimate!M196 -> 0 | F14: =Estimate!M197 -> 0 | G14: =F14 -> 0 | I14: =G14+H14 -> 0
B15: Site Concrete | E15: =Estimate!M230 -> 0 | F15: =Estimate!M231 -> 0 | G15: =F15 -> 0 | I15: =G15+H15 -> 0 | O15: PRECON BUDGET
B16: Asphalt Paving | E16: =Estimate!M245+Estimate!M262 -> 0 | F16: =Estimate!M246+Estimate!M263 -> 0 | G16: =F16 -> 0 | I16: =G16+H16 -> 0 | O16: Design Coord. | P16: =Estimate!M1229 -> 0
B17: Landscaping | E17: =Estimate!M281 -> 0 | F17: =Estimate!M282 -> 0 | G17: =F17 -> 0 | I17: =G17+H17 -> 0 | O17: GC's | P17: ='General Conditions'!L10 -> 0
B18: Fencing | E18: =Estimate!M297 -> 0 | F18: =Estimate!M298 -> 0 | G18: =F18 -> 0 | I18: =G18+H18 -> 0 | O18: TOTAL | P18: =P16+P17 -> 0
B19: Retaining Walls | E19: =Estimate!M307 -> 0 | F19: =Estimate!M308 -> 0 | G19: =F19 -> 0 | I19: =G19+H19 -> 0
B20: Misc Site Improvements | E20: =Estimate!M324 -> 0 | F20: =Estimate!M325 -> 0 | G20: =F20 -> 0 | I20: =G20+H20 -> 0
B21: Concrete | E21: =Estimate!M358+Estimate!M378+Estimate!M386+Estimate!M400+Estimate!M413 -> 0 | F21: =Estimate!M359+Estimate!M379+Estimate!M387+Estimate!M401+Estimate!M414 -> 0 | G21: =F21 -> 0 | I21: =G21+H21 -> 0
B22: Masonry | E22: =Estimate!M424 -> 0 | F22: =Estimate!M425 -> 0 | G22: =F22 -> 0 | I22: =G22+H22 -> 0
B23: Structural & Misc Steel / Erection | E23: =Estimate!M451+Estimate!M474+Estimate!M506 -> 0 | F23: =Estimate!M452+Estimate!M475+Estimate!M507 -> 0 | G23: =F23 -> 0 | I23: =G23+H23 -> 0
B24: Joists & Decking | E24: =Estimate!M491 -> 0 | F24: =Estimate!M492 -> 0 | G24: =F24 -> 0 | I24: =G24+H24 -> 0
B25: Finish Carpentry | E25: =Estimate!M535 -> 0 | F25: =Estimate!M536 -> 0 | G25: =F25 -> 0 | I25: =G25+H25 -> 0
B26: Water & Fireproofiong | E26: =Estimate!M577 -> 0 | F26: =Estimate!M578 -> 0 | G26: =F26 -> 0 | I26: =G26+H26 -> 0
B27: Metal Panels & Canopies | E27: =Estimate!M578+Estimate!M566 -> 0 | F27: =Estimate!M579+Estimate!M567 -> 0 | G27: =F27 -> 0 | I27: =G27+H27 -> 0
B28: Roofing | E28: =Estimate!M603 -> 0 | F28: =Estimate!M604 -> 0 | G28: =F28 -> 0 | I28: =G28+H28 -> 0
B29: Caulking | E29: =Estimate!M619 -> 0 | F29: =Estimate!M620 -> 0 | G29: =F29 -> 0 | I29: =G29+H29 -> 0
B30: Doors & Frames | E30: =Estimate!M661+Estimate!M631 -> 0 | F30: =Estimate!M662+Estimate!M632 -> 0 | G30: =F30 -> 0 | I30: =G30+H30 -> 0
B31: Overhead Doors | E31: =Estimate!M631 -> 0 | F31: =Estimate!M632 -> 0 | G31: =F31 -> 0 | I31: =G31+H31 -> 0
B32: Glass & Glazing | E32: =Estimate!M682 -> 0 | F32: =Estimate!M683 -> 0 | G32: =F32 -> 0 | I32: =G32+H32 -> 0
B33: Framing / Drywall / Furnishings | E33: =Estimate!M700+Estimate!M709+Estimate!M877 -> 0 | F33: =Estimate!M701+Estimate!M710+Estimate!M878 -> 0 | G33: =F33 -> 0 | I33: =G33+H33 -> 0
B34: Flooring | E34: =Estimate!M730 -> 0 | F34: =Estimate!M731 -> 0 | G34: =F34 -> 0 | I34: =G34+H34 -> 0
B35: Painting | E35: =Estimate!M749+Estimate!M791 -> 0 | F35: =Estimate!M750+Estimate!M792 -> 0 | G35: =F35 -> 0 | I35: =G35+H35 -> 0
B36: Specialties | E36: =Estimate!M827 -> 0 | F36: =Estimate!M828 -> 0 | G36: =F36 -> 0 | I36: =G36+H36 -> 0
B37: Dock Equipment / Food Service Equip | E37: =Estimate!M850+Estimate!M867 -> 0 | F37: =Estimate!M851+Estimate!M868 -> 0 | G37: =F37 -> 0 | I37: =G37+H37 -> 0
B38: PEMB | E38: =Estimate!M888 -> 0 | F38: =Estimate!M889 -> 0 | G38: =F38 -> 0 | I38: =G38+H38 -> 0
B39: Elevators / Cranes | E39: =Estimate!M906+Estimate!M899 -> 0 | F39: =Estimate!M907+Estimate!M900 -> 0 | G39: =F39 -> 0 | I39: =G39+H39 -> 0
B40: Fire Protection | E40: =Estimate!M927 -> 0 | F40: =Estimate!M928 -> 0 | G40: =F40 -> 0 | I40: =G40+H40 -> 0
B41: Plumbing | E41: =Estimate!M964+Estimate!M985 -> 0 | F41: =Estimate!M965+Estimate!M986 -> 0 | G41: =F41 -> 0 | I41: =G41+H41 -> 0
B42: Mechanical | E42: =Estimate!M1012+Estimate!M1038 -> 0 | F42: =Estimate!M1013+Estimate!M1039 -> 0 | G42: =F42 -> 0 | I42: =G42+H42 -> 0
B43: Electrical | E43: =Estimate!M1062+Estimate!M1103+Estimate!M1076+Estimate!M1124+Estimate!M1152+Estimate!M1166+Estimate!M1176+Estimate!M1188+Estimate!M1196+Estimate!M1205 -> 0 | F43: =Estimate!M1063+Estimate!M1104+Estimate!M1077+Estimate!M1125+Estimate!M1153+Estimate!M1167+Estimate!M1177+Estimate!M1189+Estimate!M1197+Estimate!M1206 -> 0 | G43: =F43 -> 0 | I43: =G43+H43 -> 0
...

Sheet How to Use
A1: Sheet Name | B1: Purpose | C1: Instructions
A2: Project Info Input | B2: Input basic project details like client name, project name, and location. | C2: Enter required project information in the highlighted fields.
A3: Budget Summary | B3: Summarizes the project's total budget after inputs. | C3: Review after filling out the 'Estimate' and 'GCs Input' sheets to check the overall budget.
A4: Estimate | B4: Breaks down detailed estimate of project including materials, labor, etc. | C4: Input quantities, unit prices, and descriptions of materials and labor.
A5: Clarifications | B5: Notes or clarifications about the estimate assumptions or conditions. | C5: Add clarifying notes to explain the scope and boundaries of the estimate.
A6: GCs Input, Staff & IT Costs | B6: Input for general conditions, staff salaries, and IT expenses related to the project. | C6: Enter salaries, overheads, and other related general condition costs.
A7: General Conditions | B7: Tracks general costs like overhead and site costs. | C7: Verify automatic calculations from the 'GCs Input' sheet.
A8: Estimate Risk Summary | B8: Summarizes risks that could impact the estimate. | C8: Document risks that might affect the budget or timeline.
